[2025-10-02T06:16:00.272+0000] {local_task_job_runner.py:120} INFO - ::group::Pre task execution logs
[2025-10-02T06:16:00.278+0000] {taskinstance.py:2076} INFO - Dependencies all met for dep_context=non-requeueable deps ti=<TaskInstance: sentiment140_end2end_single.copy_clean_into_snowflake manual__2025-10-02T05:49:37.488539+00:00 [queued]>
[2025-10-02T06:16:00.281+0000] {taskinstance.py:2076} INFO - Dependencies all met for dep_context=requeueable deps ti=<TaskInstance: sentiment140_end2end_single.copy_clean_into_snowflake manual__2025-10-02T05:49:37.488539+00:00 [queued]>
[2025-10-02T06:16:00.281+0000] {taskinstance.py:2306} INFO - Starting attempt 2 of 2
[2025-10-02T06:16:00.285+0000] {taskinstance.py:2330} INFO - Executing <Task(PythonOperator): copy_clean_into_snowflake> on 2025-10-02 05:49:37.488539+00:00
[2025-10-02T06:16:00.289+0000] {warnings.py:110} WARNING - /home/***/.local/lib/python3.12/site-packages/***/task/task_runner/standard_task_runner.py:61: DeprecationWarning: This process (pid=694) is multi-threaded, use of fork() may lead to deadlocks in the child.
  pid = os.fork()

[2025-10-02T06:16:00.290+0000] {standard_task_runner.py:63} INFO - Started process 696 to run task
[2025-10-02T06:16:00.290+0000] {standard_task_runner.py:90} INFO - Running: ['***', 'tasks', 'run', 'sentiment140_end2end_single', 'copy_clean_into_snowflake', 'manual__2025-10-02T05:49:37.488539+00:00', '--job-id', '60', '--raw', '--subdir', 'DAGS_FOLDER/edaproject.py', '--cfg-path', '/tmp/tmptypuyf33']
[2025-10-02T06:16:00.291+0000] {standard_task_runner.py:91} INFO - Job 60: Subtask copy_clean_into_snowflake
[2025-10-02T06:16:00.310+0000] {task_command.py:426} INFO - Running <TaskInstance: sentiment140_end2end_single.copy_clean_into_snowflake manual__2025-10-02T05:49:37.488539+00:00 [running]> on host b4099255ca46
[2025-10-02T06:16:00.339+0000] {taskinstance.py:2648} INFO - Exporting env vars: AIRFLOW_CTX_DAG_OWNER='***' AIRFLOW_CTX_DAG_ID='sentiment140_end2end_single' AIRFLOW_CTX_TASK_ID='copy_clean_into_snowflake' AIRFLOW_CTX_EXECUTION_DATE='2025-10-02T05:49:37.488539+00:00' AIRFLOW_CTX_TRY_NUMBER='2' AIRFLOW_CTX_DAG_RUN_ID='manual__2025-10-02T05:49:37.488539+00:00'
[2025-10-02T06:16:00.340+0000] {taskinstance.py:430} INFO - ::endgroup::
[2025-10-02T06:16:00.352+0000] {base.py:84} INFO - Using connection ID 'aws_default' for task execution.
[2025-10-02T06:16:00.353+0000] {connection_wrapper.py:384} INFO - AWS Connection (conn_id='aws_default', conn_type='aws') credentials retrieved from login and password.
[2025-10-02T06:16:00.360+0000] {base.py:84} INFO - Using connection ID 'snowflake_default' for task execution.
[2025-10-02T06:16:00.360+0000] {connection.py:399} INFO - Snowflake Connector for Python Version: 3.10.0, Python Version: 3.12.3, Platform: Linux-6.10.14-linuxkit-aarch64-with-glibc2.36
[2025-10-02T06:16:00.360+0000] {connection.py:1239} INFO - This connection is in OCSP Fail Open Mode. TLS Certificates would be checked for validity and revocation status. Any other Certificate Revocation related exceptions or OCSP Responder failures would be disregarded in favor of connectivity.
[2025-10-02T06:16:01.557+0000] {cursor.py:1149} INFO - Number of results in first chunk: 1
[2025-10-02T06:16:01.557+0000] {sql.py:470} INFO - Running statement: USE WAREHOUSE COMPUTE_WH;, parameters: None
[2025-10-02T06:16:01.701+0000] {cursor.py:1149} INFO - Number of results in first chunk: 1
[2025-10-02T06:16:01.701+0000] {sql.py:479} INFO - Rows affected: 1
[2025-10-02T06:16:01.702+0000] {snowflake.py:407} INFO - Rows affected: 1
[2025-10-02T06:16:01.702+0000] {snowflake.py:408} INFO - Snowflake query id: 01bf6f58-0306-91dc-0000-00131e67e01d
[2025-10-02T06:16:01.702+0000] {sql.py:470} INFO - Running statement: USE ROLE ACCOUNTADMIN;, parameters: None
[2025-10-02T06:16:01.852+0000] {cursor.py:1149} INFO - Number of results in first chunk: 1
[2025-10-02T06:16:01.853+0000] {sql.py:479} INFO - Rows affected: 1
[2025-10-02T06:16:01.854+0000] {snowflake.py:407} INFO - Rows affected: 1
[2025-10-02T06:16:01.854+0000] {snowflake.py:408} INFO - Snowflake query id: 01bf6f58-0306-904a-0000-00131e67612d
[2025-10-02T06:16:01.855+0000] {sql.py:470} INFO - Running statement: USE DATABASE YOUR_DB;, parameters: None
[2025-10-02T06:16:01.981+0000] {cursor.py:1149} INFO - Number of results in first chunk: 1
[2025-10-02T06:16:01.982+0000] {sql.py:479} INFO - Rows affected: 1
[2025-10-02T06:16:01.982+0000] {snowflake.py:407} INFO - Rows affected: 1
[2025-10-02T06:16:01.983+0000] {snowflake.py:408} INFO - Snowflake query id: 01bf6f58-0306-91dc-0000-00131e67e021
[2025-10-02T06:16:01.983+0000] {sql.py:470} INFO - Running statement: USE SCHEMA PUBLIC;, parameters: None
[2025-10-02T06:16:02.076+0000] {cursor.py:1149} INFO - Number of results in first chunk: 1
[2025-10-02T06:16:02.078+0000] {sql.py:479} INFO - Rows affected: 1
[2025-10-02T06:16:02.078+0000] {snowflake.py:407} INFO - Rows affected: 1
[2025-10-02T06:16:02.079+0000] {snowflake.py:408} INFO - Snowflake query id: 01bf6f58-0306-908d-0000-00131e67815d
[2025-10-02T06:16:02.079+0000] {sql.py:470} INFO - Running statement: 
    COPY INTO YOUR_DB.PUBLIC.SENTIMENT140_CLEAN
    FROM 's3://298a1/sentiment140/cleaned/20251002T060510Z/'
    CREDENTIALS=(AWS_KEY_ID='AKIA6FAWABT26ZPML6YE' AWS_SECRET_KEY='***')
    FILE_FORMAT = (TYPE=CSV FIELD_OPTIONALLY_ENCLOSED_BY='"' SKIP_HEADER=1 COMPRESSION=AUTO)
    PATTERN='.*';
    , parameters: None
[2025-10-02T06:16:03.584+0000] {connection.py:762} INFO - closed
[2025-10-02T06:16:03.741+0000] {connection.py:768} INFO - No async queries seem to be running, deleting session
[2025-10-02T06:16:03.810+0000] {taskinstance.py:441} INFO - ::group::Post task execution logs
[2025-10-02T06:16:03.813+0000] {taskinstance.py:2905} ERROR - Task failed with exception
Traceback (most recent call last):
  File "/home/airflow/.local/lib/python3.12/site-packages/airflow/models/taskinstance.py", line 465, in _execute_task
    result = _execute_callable(context=context, **execute_callable_kwargs)
             ^^^^^^^^^^^^^^^^^^^^^^^^^^^^^^^^^^^^^^^^^^^^^^^^^^^^^^^^^^^^^
  File "/home/airflow/.local/lib/python3.12/site-packages/airflow/models/taskinstance.py", line 432, in _execute_callable
    return execute_callable(context=context, **execute_callable_kwargs)
           ^^^^^^^^^^^^^^^^^^^^^^^^^^^^^^^^^^^^^^^^^^^^^^^^^^^^^^^^^^^^
  File "/home/airflow/.local/lib/python3.12/site-packages/airflow/models/baseoperator.py", line 400, in wrapper
    return func(self, *args, **kwargs)
           ^^^^^^^^^^^^^^^^^^^^^^^^^^^
  File "/home/airflow/.local/lib/python3.12/site-packages/airflow/operators/python.py", line 235, in execute
    return_value = self.execute_callable()
                   ^^^^^^^^^^^^^^^^^^^^^^^
  File "/home/airflow/.local/lib/python3.12/site-packages/airflow/operators/python.py", line 252, in execute_callable
    return self.python_callable(*self.op_args, **self.op_kwargs)
           ^^^^^^^^^^^^^^^^^^^^^^^^^^^^^^^^^^^^^^^^^^^^^^^^^^^^^
  File "/opt/airflow/dags/edaproject.py", line 359, in _copy_clean_into_snowflake
    sf.run([
  File "/home/airflow/.local/lib/python3.12/site-packages/airflow/providers/snowflake/hooks/snowflake.py", line 395, in run
    self._run_command(cur, sql_statement, parameters)  # type: ignore[attr-defined]
    ^^^^^^^^^^^^^^^^^^^^^^^^^^^^^^^^^^^^^^^^^^^^^^^^^
  File "/home/airflow/.local/lib/python3.12/site-packages/airflow/providers/common/sql/hooks/sql.py", line 475, in _run_command
    cur.execute(sql_statement)
  File "/home/airflow/.local/lib/python3.12/site-packages/snowflake/connector/cursor.py", line 1080, in execute
    Error.errorhandler_wrapper(self.connection, self, error_class, errvalue)
  File "/home/airflow/.local/lib/python3.12/site-packages/snowflake/connector/errors.py", line 290, in errorhandler_wrapper
    handed_over = Error.hand_to_other_handler(
                  ^^^^^^^^^^^^^^^^^^^^^^^^^^^^
  File "/home/airflow/.local/lib/python3.12/site-packages/snowflake/connector/errors.py", line 345, in hand_to_other_handler
    cursor.errorhandler(connection, cursor, error_class, error_value)
  File "/home/airflow/.local/lib/python3.12/site-packages/snowflake/connector/errors.py", line 221, in default_errorhandler
    raise error_class(
snowflake.connector.errors.ProgrammingError: 100016 (22000): 01bf6f58-0306-8f79-0000-00131e67c111: Field delimiter ',' found while expecting record delimiter '\n'
  File 'sentiment140/cleaned/20251002T060510Z/MAUD_train_cleaned.csv', line 189387, character 2
  Row 189385 starts at line 189386, column "SENTIMENT140_CLEAN"["TEXT":2]
  If you would like to continue loading when an error is encountered, use other values such as 'SKIP_FILE' or 'CONTINUE' for the ON_ERROR option. For more information on loading options, please run 'info loading_data' in a SQL client.
[2025-10-02T06:16:03.827+0000] {taskinstance.py:1206} INFO - Marking task as FAILED. dag_id=sentiment140_end2end_single, task_id=copy_clean_into_snowflake, run_id=manual__2025-10-02T05:49:37.488539+00:00, execution_date=20251002T054937, start_date=20251002T061600, end_date=20251002T061603
[2025-10-02T06:16:03.840+0000] {standard_task_runner.py:110} ERROR - Failed to execute job 60 for task copy_clean_into_snowflake (100016 (22000): 01bf6f58-0306-8f79-0000-00131e67c111: Field delimiter ',' found while expecting record delimiter '\n'
  File 'sentiment140/cleaned/20251002T060510Z/MAUD_train_cleaned.csv', line 189387, character 2
  Row 189385 starts at line 189386, column "SENTIMENT140_CLEAN"["TEXT":2]
  If you would like to continue loading when an error is encountered, use other values such as 'SKIP_FILE' or 'CONTINUE' for the ON_ERROR option. For more information on loading options, please run 'info loading_data' in a SQL client.; 696)
[2025-10-02T06:16:03.854+0000] {local_task_job_runner.py:240} INFO - Task exited with return code 1
[2025-10-02T06:16:03.870+0000] {taskinstance.py:3498} INFO - 0 downstream tasks scheduled from follow-on schedule check
[2025-10-02T06:16:03.873+0000] {local_task_job_runner.py:222} INFO - ::endgroup::
