[2025-10-02T05:52:53.716+0000] {local_task_job_runner.py:120} INFO - ::group::Pre task execution logs
[2025-10-02T05:52:53.722+0000] {taskinstance.py:2076} INFO - Dependencies all met for dep_context=non-requeueable deps ti=<TaskInstance: sentiment140_end2end_single.run_eda_and_clean manual__2025-10-02T05:52:43.264598+00:00 [queued]>
[2025-10-02T05:52:53.725+0000] {taskinstance.py:2076} INFO - Dependencies all met for dep_context=requeueable deps ti=<TaskInstance: sentiment140_end2end_single.run_eda_and_clean manual__2025-10-02T05:52:43.264598+00:00 [queued]>
[2025-10-02T05:52:53.725+0000] {taskinstance.py:2306} INFO - Starting attempt 1 of 2
[2025-10-02T05:52:53.729+0000] {taskinstance.py:2330} INFO - Executing <Task(PythonOperator): run_eda_and_clean> on 2025-10-02 05:52:43.264598+00:00
[2025-10-02T05:52:53.733+0000] {standard_task_runner.py:90} INFO - Running: ['***', 'tasks', 'run', 'sentiment140_end2end_single', 'run_eda_and_clean', 'manual__2025-10-02T05:52:43.264598+00:00', '--job-id', '33', '--raw', '--subdir', 'DAGS_FOLDER/edaproject.py', '--cfg-path', '/tmp/tmpsofscm6b']
[2025-10-02T05:52:53.739+0000] {standard_task_runner.py:91} INFO - Job 33: Subtask run_eda_and_clean
[2025-10-02T05:52:53.734+0000] {warnings.py:110} WARNING - /home/***/.local/lib/python3.12/site-packages/***/task/task_runner/standard_task_runner.py:61: DeprecationWarning: This process (pid=466) is multi-threaded, use of fork() may lead to deadlocks in the child.
  pid = os.fork()

[2025-10-02T05:52:53.742+0000] {standard_task_runner.py:63} INFO - Started process 468 to run task
[2025-10-02T05:52:53.762+0000] {task_command.py:426} INFO - Running <TaskInstance: sentiment140_end2end_single.run_eda_and_clean manual__2025-10-02T05:52:43.264598+00:00 [running]> on host 590373856cb4
[2025-10-02T05:52:53.788+0000] {taskinstance.py:2648} INFO - Exporting env vars: AIRFLOW_CTX_DAG_OWNER='***' AIRFLOW_CTX_DAG_ID='sentiment140_end2end_single' AIRFLOW_CTX_TASK_ID='run_eda_and_clean' AIRFLOW_CTX_EXECUTION_DATE='2025-10-02T05:52:43.264598+00:00' AIRFLOW_CTX_TRY_NUMBER='1' AIRFLOW_CTX_DAG_RUN_ID='manual__2025-10-02T05:52:43.264598+00:00'
[2025-10-02T05:52:53.789+0000] {taskinstance.py:430} INFO - ::endgroup::
[2025-10-02T05:53:14.673+0000] {taskinstance.py:441} INFO - ::group::Post task execution logs
[2025-10-02T05:53:14.675+0000] {taskinstance.py:2905} ERROR - Task failed with exception
Traceback (most recent call last):
  File "/home/airflow/.local/lib/python3.12/site-packages/airflow/models/taskinstance.py", line 465, in _execute_task
    result = _execute_callable(context=context, **execute_callable_kwargs)
             ^^^^^^^^^^^^^^^^^^^^^^^^^^^^^^^^^^^^^^^^^^^^^^^^^^^^^^^^^^^^^
  File "/home/airflow/.local/lib/python3.12/site-packages/airflow/models/taskinstance.py", line 432, in _execute_callable
    return execute_callable(context=context, **execute_callable_kwargs)
           ^^^^^^^^^^^^^^^^^^^^^^^^^^^^^^^^^^^^^^^^^^^^^^^^^^^^^^^^^^^^
  File "/home/airflow/.local/lib/python3.12/site-packages/airflow/models/baseoperator.py", line 400, in wrapper
    return func(self, *args, **kwargs)
           ^^^^^^^^^^^^^^^^^^^^^^^^^^^
  File "/home/airflow/.local/lib/python3.12/site-packages/airflow/operators/python.py", line 235, in execute
    return_value = self.execute_callable()
                   ^^^^^^^^^^^^^^^^^^^^^^^
  File "/home/airflow/.local/lib/python3.12/site-packages/airflow/operators/python.py", line 252, in execute_callable
    return self.python_callable(*self.op_args, **self.op_kwargs)
           ^^^^^^^^^^^^^^^^^^^^^^^^^^^^^^^^^^^^^^^^^^^^^^^^^^^^^
  File "/opt/airflow/dags/edaproject.py", line 268, in _run_eda_and_clean
    save_plot_hist_from_counts(char_bins, hist_chars, "Tweet Character Lengths", "Characters", chars_png)
  File "/opt/airflow/dags/edaproject.py", line 252, in save_plot_hist_from_counts
    import matplotlib.pyplot as plt
ModuleNotFoundError: No module named 'matplotlib'
[2025-10-02T05:53:14.681+0000] {taskinstance.py:1206} INFO - Marking task as UP_FOR_RETRY. dag_id=sentiment140_end2end_single, task_id=run_eda_and_clean, run_id=manual__2025-10-02T05:52:43.264598+00:00, execution_date=20251002T055243, start_date=20251002T055253, end_date=20251002T055314
[2025-10-02T05:53:14.687+0000] {standard_task_runner.py:110} ERROR - Failed to execute job 33 for task run_eda_and_clean (No module named 'matplotlib'; 468)
[2025-10-02T05:53:14.730+0000] {local_task_job_runner.py:240} INFO - Task exited with return code 1
[2025-10-02T05:53:14.748+0000] {taskinstance.py:3498} INFO - 0 downstream tasks scheduled from follow-on schedule check
[2025-10-02T05:53:14.749+0000] {local_task_job_runner.py:222} INFO - ::endgroup::
