[2025-10-02T06:03:53.391+0000] {local_task_job_runner.py:120} INFO - ::group::Pre task execution logs
[2025-10-02T06:03:53.396+0000] {taskinstance.py:2076} INFO - Dependencies all met for dep_context=non-requeueable deps ti=<TaskInstance: sentiment140_end2end_single.create_table_if_needed manual__2025-10-02T05:52:43.264598+00:00 [queued]>
[2025-10-02T06:03:53.399+0000] {taskinstance.py:2076} INFO - Dependencies all met for dep_context=requeueable deps ti=<TaskInstance: sentiment140_end2end_single.create_table_if_needed manual__2025-10-02T05:52:43.264598+00:00 [queued]>
[2025-10-02T06:03:53.399+0000] {taskinstance.py:2306} INFO - Starting attempt 2 of 2
[2025-10-02T06:03:53.403+0000] {taskinstance.py:2330} INFO - Executing <Task(PythonOperator): create_table_if_needed> on 2025-10-02 05:52:43.264598+00:00
[2025-10-02T06:03:53.407+0000] {warnings.py:110} WARNING - /home/***/.local/lib/python3.12/site-packages/***/task/task_runner/standard_task_runner.py:61: DeprecationWarning: This process (pid=362) is multi-threaded, use of fork() may lead to deadlocks in the child.
  pid = os.fork()

[2025-10-02T06:03:53.408+0000] {standard_task_runner.py:63} INFO - Started process 364 to run task
[2025-10-02T06:03:53.408+0000] {standard_task_runner.py:90} INFO - Running: ['***', 'tasks', 'run', 'sentiment140_end2end_single', 'create_table_if_needed', 'manual__2025-10-02T05:52:43.264598+00:00', '--job-id', '47', '--raw', '--subdir', 'DAGS_FOLDER/edaproject.py', '--cfg-path', '/tmp/tmps1e_wv0z']
[2025-10-02T06:03:53.410+0000] {standard_task_runner.py:91} INFO - Job 47: Subtask create_table_if_needed
[2025-10-02T06:03:53.427+0000] {task_command.py:426} INFO - Running <TaskInstance: sentiment140_end2end_single.create_table_if_needed manual__2025-10-02T05:52:43.264598+00:00 [running]> on host b4099255ca46
[2025-10-02T06:03:53.457+0000] {taskinstance.py:2648} INFO - Exporting env vars: AIRFLOW_CTX_DAG_OWNER='***' AIRFLOW_CTX_DAG_ID='sentiment140_end2end_single' AIRFLOW_CTX_TASK_ID='create_table_if_needed' AIRFLOW_CTX_EXECUTION_DATE='2025-10-02T05:52:43.264598+00:00' AIRFLOW_CTX_TRY_NUMBER='2' AIRFLOW_CTX_DAG_RUN_ID='manual__2025-10-02T05:52:43.264598+00:00'
[2025-10-02T06:03:53.457+0000] {taskinstance.py:430} INFO - ::endgroup::
[2025-10-02T06:03:53.466+0000] {base.py:84} INFO - Using connection ID 'snowflake_default' for task execution.
[2025-10-02T06:03:53.467+0000] {connection.py:399} INFO - Snowflake Connector for Python Version: 3.10.0, Python Version: 3.12.3, Platform: Linux-6.10.14-linuxkit-aarch64-with-glibc2.36
[2025-10-02T06:03:53.467+0000] {connection.py:1239} INFO - This connection is in OCSP Fail Open Mode. TLS Certificates would be checked for validity and revocation status. Any other Certificate Revocation related exceptions or OCSP Responder failures would be disregarded in favor of connectivity.
[2025-10-02T06:03:54.130+0000] {taskinstance.py:441} INFO - ::group::Post task execution logs
[2025-10-02T06:03:54.131+0000] {taskinstance.py:2905} ERROR - Task failed with exception
Traceback (most recent call last):
  File "/home/airflow/.local/lib/python3.12/site-packages/airflow/models/taskinstance.py", line 465, in _execute_task
    result = _execute_callable(context=context, **execute_callable_kwargs)
             ^^^^^^^^^^^^^^^^^^^^^^^^^^^^^^^^^^^^^^^^^^^^^^^^^^^^^^^^^^^^^
  File "/home/airflow/.local/lib/python3.12/site-packages/airflow/models/taskinstance.py", line 432, in _execute_callable
    return execute_callable(context=context, **execute_callable_kwargs)
           ^^^^^^^^^^^^^^^^^^^^^^^^^^^^^^^^^^^^^^^^^^^^^^^^^^^^^^^^^^^^
  File "/home/airflow/.local/lib/python3.12/site-packages/airflow/models/baseoperator.py", line 400, in wrapper
    return func(self, *args, **kwargs)
           ^^^^^^^^^^^^^^^^^^^^^^^^^^^
  File "/home/airflow/.local/lib/python3.12/site-packages/airflow/operators/python.py", line 235, in execute
    return_value = self.execute_callable()
                   ^^^^^^^^^^^^^^^^^^^^^^^
  File "/home/airflow/.local/lib/python3.12/site-packages/airflow/operators/python.py", line 252, in execute_callable
    return self.python_callable(*self.op_args, **self.op_kwargs)
           ^^^^^^^^^^^^^^^^^^^^^^^^^^^^^^^^^^^^^^^^^^^^^^^^^^^^^
  File "/opt/airflow/dags/edaproject.py", line 320, in _create_table_if_needed
    sf.run([
  File "/home/airflow/.local/lib/python3.12/site-packages/airflow/providers/snowflake/hooks/snowflake.py", line 389, in run
    with closing(self.get_conn()) as conn:
                 ^^^^^^^^^^^^^^^
  File "/home/airflow/.local/lib/python3.12/site-packages/airflow/providers/snowflake/hooks/snowflake.py", line 287, in get_conn
    conn = connector.connect(**conn_config)
           ^^^^^^^^^^^^^^^^^^^^^^^^^^^^^^^^
  File "/home/airflow/.local/lib/python3.12/site-packages/snowflake/connector/__init__.py", line 55, in Connect
    return SnowflakeConnection(**kwargs)
           ^^^^^^^^^^^^^^^^^^^^^^^^^^^^^
  File "/home/airflow/.local/lib/python3.12/site-packages/snowflake/connector/connection.py", line 442, in __init__
    self.connect(**kwargs)
  File "/home/airflow/.local/lib/python3.12/site-packages/snowflake/connector/connection.py", line 745, in connect
    self.__open_connection()
  File "/home/airflow/.local/lib/python3.12/site-packages/snowflake/connector/connection.py", line 1073, in __open_connection
    self.authenticate_with_retry(self.auth_class)
  File "/home/airflow/.local/lib/python3.12/site-packages/snowflake/connector/connection.py", line 1345, in authenticate_with_retry
    self._authenticate(auth_instance)
  File "/home/airflow/.local/lib/python3.12/site-packages/snowflake/connector/connection.py", line 1373, in _authenticate
    auth.authenticate(
  File "/home/airflow/.local/lib/python3.12/site-packages/snowflake/connector/auth/_auth.py", line 250, in authenticate
    ret = self._rest._post_request(
          ^^^^^^^^^^^^^^^^^^^^^^^^^
  File "/home/airflow/.local/lib/python3.12/site-packages/snowflake/connector/network.py", line 734, in _post_request
    ret = self.fetch(
          ^^^^^^^^^^^
  File "/home/airflow/.local/lib/python3.12/site-packages/snowflake/connector/network.py", line 843, in fetch
    ret = self._request_exec_wrapper(
          ^^^^^^^^^^^^^^^^^^^^^^^^^^^
  File "/home/airflow/.local/lib/python3.12/site-packages/snowflake/connector/network.py", line 979, in _request_exec_wrapper
    raise e
  File "/home/airflow/.local/lib/python3.12/site-packages/snowflake/connector/network.py", line 884, in _request_exec_wrapper
    return_object = self._request_exec(
                    ^^^^^^^^^^^^^^^^^^^
  File "/home/airflow/.local/lib/python3.12/site-packages/snowflake/connector/network.py", line 1193, in _request_exec
    raise err
  File "/home/airflow/.local/lib/python3.12/site-packages/snowflake/connector/network.py", line 1135, in _request_exec
    raise_failed_request_error(
  File "/home/airflow/.local/lib/python3.12/site-packages/snowflake/connector/network.py", line 238, in raise_failed_request_error
    Error.errorhandler_wrapper(
  File "/home/airflow/.local/lib/python3.12/site-packages/snowflake/connector/errors.py", line 290, in errorhandler_wrapper
    handed_over = Error.hand_to_other_handler(
                  ^^^^^^^^^^^^^^^^^^^^^^^^^^^^
  File "/home/airflow/.local/lib/python3.12/site-packages/snowflake/connector/errors.py", line 348, in hand_to_other_handler
    connection.errorhandler(connection, cursor, error_class, error_value)
  File "/home/airflow/.local/lib/python3.12/site-packages/snowflake/connector/errors.py", line 221, in default_errorhandler
    raise error_class(
snowflake.connector.errors.InterfaceError: 250003 (08001): None: 404 Not Found: post https://CDB27862.snowflakecomputing.com:443/session/v1/login-request?request_id=09a80bf1-8238-4734-8167-bfb0240855b8&databaseName=YOUR_DB&schemaName=PUBLIC&warehouse=COMPUTE_WH&roleName=&request_guid=9858ef92-9459-40e9-8043-bf63e221b360
[2025-10-02T06:03:54.139+0000] {taskinstance.py:1206} INFO - Marking task as FAILED. dag_id=sentiment140_end2end_single, task_id=create_table_if_needed, run_id=manual__2025-10-02T05:52:43.264598+00:00, execution_date=20251002T055243, start_date=20251002T060353, end_date=20251002T060354
[2025-10-02T06:03:54.147+0000] {standard_task_runner.py:110} ERROR - Failed to execute job 47 for task create_table_if_needed (250003 (08001): None: 404 Not Found: post https://CDB27862.snowflakecomputing.com:443/session/v1/login-request?request_id=09a80bf1-8238-4734-8167-bfb0240855b8&databaseName=YOUR_DB&schemaName=PUBLIC&warehouse=COMPUTE_WH&roleName=&request_guid=9858ef92-9459-40e9-8043-bf63e221b360; 364)
[2025-10-02T06:03:54.186+0000] {local_task_job_runner.py:240} INFO - Task exited with return code 1
[2025-10-02T06:03:54.198+0000] {taskinstance.py:3498} INFO - 0 downstream tasks scheduled from follow-on schedule check
[2025-10-02T06:03:54.199+0000] {local_task_job_runner.py:222} INFO - ::endgroup::
